2024-06-27 08:36:58,676 INFO    MainThread:306479 [wandb_setup.py:_flush():76] Current SDK version is 0.17.1
2024-06-27 08:36:58,676 INFO    MainThread:306479 [wandb_setup.py:_flush():76] Configure stats pid to 306479
2024-06-27 08:36:58,676 INFO    MainThread:306479 [wandb_setup.py:_flush():76] Loading settings from /home/tzikos/.config/wandb/settings
2024-06-27 08:36:58,676 INFO    MainThread:306479 [wandb_setup.py:_flush():76] Loading settings from /home/tzikos/Desktop/KULeuvenThesis/wandb/settings
2024-06-27 08:36:58,676 INFO    MainThread:306479 [wandb_setup.py:_flush():76] Loading settings from environment variables: {}
2024-06-27 08:36:58,676 INFO    MainThread:306479 [wandb_setup.py:_flush():76] Applying setup settings: {'_disable_service': False}
2024-06-27 08:36:58,676 INFO    MainThread:306479 [wandb_setup.py:_flush():76] Inferring run settings from compute environment: {'program_relpath': 'main.py', 'program_abspath': '/home/tzikos/Desktop/KULeuvenThesis/main.py', 'program': '/home/tzikos/Desktop/KULeuvenThesis/main.py'}
2024-06-27 08:36:58,676 INFO    MainThread:306479 [wandb_setup.py:_flush():76] Applying login settings: {}
2024-06-27 08:36:58,676 INFO    MainThread:306479 [wandb_init.py:_log_setup():520] Logging user logs to /home/tzikos/Desktop/KULeuvenThesis/wandb/run-20240627_083658-iefu1zd6/logs/debug.log
2024-06-27 08:36:58,676 INFO    MainThread:306479 [wandb_init.py:_log_setup():521] Logging internal logs to /home/tzikos/Desktop/KULeuvenThesis/wandb/run-20240627_083658-iefu1zd6/logs/debug-internal.log
2024-06-27 08:36:58,677 INFO    MainThread:306479 [wandb_init.py:init():560] calling init triggers
2024-06-27 08:36:58,677 INFO    MainThread:306479 [wandb_init.py:init():567] wandb.init called with sweep_config: {}
config: {'learning_rate': 1e-05, 'batch_size': 64, 'L1': None, 'L2': None, 'A': 1, 'early_patience': 12, 'reduce_lr_patience': 5, 'architecture': 'ECGCNNClassifier', 'experiment': 'tachy', 'use_pretrained': False}
2024-06-27 08:36:58,677 INFO    MainThread:306479 [wandb_init.py:init():610] starting backend
2024-06-27 08:36:58,677 INFO    MainThread:306479 [wandb_init.py:init():614] setting up manager
2024-06-27 08:36:58,679 INFO    MainThread:306479 [backend.py:_multiprocessing_setup():105] multiprocessing start_methods=fork,spawn,forkserver, using: spawn
2024-06-27 08:36:58,681 INFO    MainThread:306479 [wandb_init.py:init():622] backend started and connected
2024-06-27 08:36:58,685 INFO    MainThread:306479 [wandb_init.py:init():711] updated telemetry
2024-06-27 08:36:58,692 INFO    MainThread:306479 [wandb_init.py:init():744] communicating run to backend with 90.0 second timeout
2024-06-27 08:36:59,440 INFO    MainThread:306479 [wandb_run.py:_on_init():2402] communicating current version
2024-06-27 08:36:59,835 INFO    MainThread:306479 [wandb_run.py:_on_init():2411] got version response upgrade_message: "wandb version 0.17.3 is available!  To upgrade, please run:\n $ pip install wandb --upgrade"

2024-06-27 08:36:59,835 INFO    MainThread:306479 [wandb_init.py:init():795] starting run threads in backend
2024-06-27 08:37:02,796 INFO    MainThread:306479 [wandb_run.py:_console_start():2380] atexit reg
2024-06-27 08:37:02,796 INFO    MainThread:306479 [wandb_run.py:_redirect():2235] redirect: wrap_raw
2024-06-27 08:37:02,796 INFO    MainThread:306479 [wandb_run.py:_redirect():2300] Wrapping output streams.
2024-06-27 08:37:02,796 INFO    MainThread:306479 [wandb_run.py:_redirect():2325] Redirects installed.
2024-06-27 08:37:02,798 INFO    MainThread:306479 [wandb_init.py:init():838] run started, returning control to user process
2024-06-27 08:38:39,823 INFO    MainThread:306479 [retry.py:__call__():172] Retry attempt failed:
Traceback (most recent call last):
  File "/home/tzikos/anaconda3/envs/KUThesis/lib/python3.12/site-packages/urllib3/connection.py", line 198, in _new_conn
    sock = connection.create_connection(
           ^^^^^^^^^^^^^^^^^^^^^^^^^^^^^
  File "/home/tzikos/anaconda3/envs/KUThesis/lib/python3.12/site-packages/urllib3/util/connection.py", line 60, in create_connection
    for res in socket.getaddrinfo(host, port, family, socket.SOCK_STREAM):
               ^^^^^^^^^^^^^^^^^^^^^^^^^^^^^^^^^^^^^^^^^^^^^^^^^^^^^^^^^^
  File "/home/tzikos/anaconda3/envs/KUThesis/lib/python3.12/socket.py", line 963, in getaddrinfo
    for res in _socket.getaddrinfo(host, port, family, type, proto, flags):
               ^^^^^^^^^^^^^^^^^^^^^^^^^^^^^^^^^^^^^^^^^^^^^^^^^^^^^^^^^^^
socket.gaierror: [Errno -3] Temporary failure in name resolution

The above exception was the direct cause of the following exception:

Traceback (most recent call last):
  File "/home/tzikos/anaconda3/envs/KUThesis/lib/python3.12/site-packages/urllib3/connectionpool.py", line 793, in urlopen
    response = self._make_request(
               ^^^^^^^^^^^^^^^^^^^
  File "/home/tzikos/anaconda3/envs/KUThesis/lib/python3.12/site-packages/urllib3/connectionpool.py", line 491, in _make_request
    raise new_e
  File "/home/tzikos/anaconda3/envs/KUThesis/lib/python3.12/site-packages/urllib3/connectionpool.py", line 467, in _make_request
    self._validate_conn(conn)
  File "/home/tzikos/anaconda3/envs/KUThesis/lib/python3.12/site-packages/urllib3/connectionpool.py", line 1099, in _validate_conn
    conn.connect()
  File "/home/tzikos/anaconda3/envs/KUThesis/lib/python3.12/site-packages/urllib3/connection.py", line 616, in connect
    self.sock = sock = self._new_conn()
                       ^^^^^^^^^^^^^^^^
  File "/home/tzikos/anaconda3/envs/KUThesis/lib/python3.12/site-packages/urllib3/connection.py", line 205, in _new_conn
    raise NameResolutionError(self.host, self, e) from e
urllib3.exceptions.NameResolutionError: <urllib3.connection.HTTPSConnection object at 0x79e8be520320>: Failed to resolve 'api.wandb.ai' ([Errno -3] Temporary failure in name resolution)

The above exception was the direct cause of the following exception:

Traceback (most recent call last):
  File "/home/tzikos/anaconda3/envs/KUThesis/lib/python3.12/site-packages/requests/adapters.py", line 486, in send
    resp = conn.urlopen(
           ^^^^^^^^^^^^^
  File "/home/tzikos/anaconda3/envs/KUThesis/lib/python3.12/site-packages/urllib3/connectionpool.py", line 847, in urlopen
    retries = retries.increment(
              ^^^^^^^^^^^^^^^^^^
  File "/home/tzikos/anaconda3/envs/KUThesis/lib/python3.12/site-packages/urllib3/util/retry.py", line 515, in increment
    raise MaxRetryError(_pool, url, reason) from reason  # type: ignore[arg-type]
    ^^^^^^^^^^^^^^^^^^^^^^^^^^^^^^^^^^^^^^^^^^^^^^^^^^^
urllib3.exceptions.MaxRetryError: HTTPSConnectionPool(host='api.wandb.ai', port=443): Max retries exceeded with url: /graphql (Caused by NameResolutionError("<urllib3.connection.HTTPSConnection object at 0x79e8be520320>: Failed to resolve 'api.wandb.ai' ([Errno -3] Temporary failure in name resolution)"))

During handling of the above exception, another exception occurred:

Traceback (most recent call last):
  File "/home/tzikos/anaconda3/envs/KUThesis/lib/python3.12/site-packages/wandb/sdk/lib/retry.py", line 131, in __call__
    result = self._call_fn(*args, **kwargs)
             ^^^^^^^^^^^^^^^^^^^^^^^^^^^^^^
  File "/home/tzikos/anaconda3/envs/KUThesis/lib/python3.12/site-packages/wandb/apis/public/api.py", line 70, in execute
    return self._client.execute(*args, **kwargs)
           ^^^^^^^^^^^^^^^^^^^^^^^^^^^^^^^^^^^^^
  File "/home/tzikos/anaconda3/envs/KUThesis/lib/python3.12/site-packages/wandb/vendor/gql-0.2.0/wandb_gql/client.py", line 52, in execute
    result = self._get_result(document, *args, **kwargs)
             ^^^^^^^^^^^^^^^^^^^^^^^^^^^^^^^^^^^^^^^^^^^
  File "/home/tzikos/anaconda3/envs/KUThesis/lib/python3.12/site-packages/wandb/vendor/gql-0.2.0/wandb_gql/client.py", line 60, in _get_result
    return self.transport.execute(document, *args, **kwargs)
           ^^^^^^^^^^^^^^^^^^^^^^^^^^^^^^^^^^^^^^^^^^^^^^^^^
  File "/home/tzikos/anaconda3/envs/KUThesis/lib/python3.12/site-packages/wandb/sdk/lib/gql_request.py", line 58, in execute
    request = self.session.post(self.url, **post_args)
              ^^^^^^^^^^^^^^^^^^^^^^^^^^^^^^^^^^^^^^^^
  File "/home/tzikos/anaconda3/envs/KUThesis/lib/python3.12/site-packages/requests/sessions.py", line 637, in post
    return self.request("POST", url, data=data, json=json, **kwargs)
           ^^^^^^^^^^^^^^^^^^^^^^^^^^^^^^^^^^^^^^^^^^^^^^^^^^^^^^^^^
  File "/home/tzikos/anaconda3/envs/KUThesis/lib/python3.12/site-packages/requests/sessions.py", line 589, in request
    resp = self.send(prep, **send_kwargs)
           ^^^^^^^^^^^^^^^^^^^^^^^^^^^^^^
  File "/home/tzikos/anaconda3/envs/KUThesis/lib/python3.12/site-packages/requests/sessions.py", line 703, in send
    r = adapter.send(request, **kwargs)
        ^^^^^^^^^^^^^^^^^^^^^^^^^^^^^^^
  File "/home/tzikos/anaconda3/envs/KUThesis/lib/python3.12/site-packages/requests/adapters.py", line 519, in send
    raise ConnectionError(e, request=request)
requests.exceptions.ConnectionError: HTTPSConnectionPool(host='api.wandb.ai', port=443): Max retries exceeded with url: /graphql (Caused by NameResolutionError("<urllib3.connection.HTTPSConnection object at 0x79e8be520320>: Failed to resolve 'api.wandb.ai' ([Errno -3] Temporary failure in name resolution)"))
2024-06-27 08:40:12,713 INFO    MainThread:306479 [retry.py:__call__():172] Retry attempt failed:
Traceback (most recent call last):
  File "/home/tzikos/anaconda3/envs/KUThesis/lib/python3.12/site-packages/urllib3/connection.py", line 198, in _new_conn
    sock = connection.create_connection(
           ^^^^^^^^^^^^^^^^^^^^^^^^^^^^^
  File "/home/tzikos/anaconda3/envs/KUThesis/lib/python3.12/site-packages/urllib3/util/connection.py", line 60, in create_connection
    for res in socket.getaddrinfo(host, port, family, socket.SOCK_STREAM):
               ^^^^^^^^^^^^^^^^^^^^^^^^^^^^^^^^^^^^^^^^^^^^^^^^^^^^^^^^^^
  File "/home/tzikos/anaconda3/envs/KUThesis/lib/python3.12/socket.py", line 963, in getaddrinfo
    for res in _socket.getaddrinfo(host, port, family, type, proto, flags):
               ^^^^^^^^^^^^^^^^^^^^^^^^^^^^^^^^^^^^^^^^^^^^^^^^^^^^^^^^^^^
socket.gaierror: [Errno -3] Temporary failure in name resolution

The above exception was the direct cause of the following exception:

Traceback (most recent call last):
  File "/home/tzikos/anaconda3/envs/KUThesis/lib/python3.12/site-packages/urllib3/connectionpool.py", line 793, in urlopen
    response = self._make_request(
               ^^^^^^^^^^^^^^^^^^^
  File "/home/tzikos/anaconda3/envs/KUThesis/lib/python3.12/site-packages/urllib3/connectionpool.py", line 491, in _make_request
    raise new_e
  File "/home/tzikos/anaconda3/envs/KUThesis/lib/python3.12/site-packages/urllib3/connectionpool.py", line 467, in _make_request
    self._validate_conn(conn)
  File "/home/tzikos/anaconda3/envs/KUThesis/lib/python3.12/site-packages/urllib3/connectionpool.py", line 1099, in _validate_conn
    conn.connect()
  File "/home/tzikos/anaconda3/envs/KUThesis/lib/python3.12/site-packages/urllib3/connection.py", line 616, in connect
    self.sock = sock = self._new_conn()
                       ^^^^^^^^^^^^^^^^
  File "/home/tzikos/anaconda3/envs/KUThesis/lib/python3.12/site-packages/urllib3/connection.py", line 205, in _new_conn
    raise NameResolutionError(self.host, self, e) from e
urllib3.exceptions.NameResolutionError: <urllib3.connection.HTTPSConnection object at 0x79e8be32fe30>: Failed to resolve 'api.wandb.ai' ([Errno -3] Temporary failure in name resolution)

The above exception was the direct cause of the following exception:

Traceback (most recent call last):
  File "/home/tzikos/anaconda3/envs/KUThesis/lib/python3.12/site-packages/requests/adapters.py", line 486, in send
    resp = conn.urlopen(
           ^^^^^^^^^^^^^
  File "/home/tzikos/anaconda3/envs/KUThesis/lib/python3.12/site-packages/urllib3/connectionpool.py", line 847, in urlopen
    retries = retries.increment(
              ^^^^^^^^^^^^^^^^^^
  File "/home/tzikos/anaconda3/envs/KUThesis/lib/python3.12/site-packages/urllib3/util/retry.py", line 515, in increment
    raise MaxRetryError(_pool, url, reason) from reason  # type: ignore[arg-type]
    ^^^^^^^^^^^^^^^^^^^^^^^^^^^^^^^^^^^^^^^^^^^^^^^^^^^
urllib3.exceptions.MaxRetryError: HTTPSConnectionPool(host='api.wandb.ai', port=443): Max retries exceeded with url: /graphql (Caused by NameResolutionError("<urllib3.connection.HTTPSConnection object at 0x79e8be32fe30>: Failed to resolve 'api.wandb.ai' ([Errno -3] Temporary failure in name resolution)"))

During handling of the above exception, another exception occurred:

Traceback (most recent call last):
  File "/home/tzikos/anaconda3/envs/KUThesis/lib/python3.12/site-packages/wandb/sdk/lib/retry.py", line 131, in __call__
    result = self._call_fn(*args, **kwargs)
             ^^^^^^^^^^^^^^^^^^^^^^^^^^^^^^
  File "/home/tzikos/anaconda3/envs/KUThesis/lib/python3.12/site-packages/wandb/apis/public/api.py", line 70, in execute
    return self._client.execute(*args, **kwargs)
           ^^^^^^^^^^^^^^^^^^^^^^^^^^^^^^^^^^^^^
  File "/home/tzikos/anaconda3/envs/KUThesis/lib/python3.12/site-packages/wandb/vendor/gql-0.2.0/wandb_gql/client.py", line 52, in execute
    result = self._get_result(document, *args, **kwargs)
             ^^^^^^^^^^^^^^^^^^^^^^^^^^^^^^^^^^^^^^^^^^^
  File "/home/tzikos/anaconda3/envs/KUThesis/lib/python3.12/site-packages/wandb/vendor/gql-0.2.0/wandb_gql/client.py", line 60, in _get_result
    return self.transport.execute(document, *args, **kwargs)
           ^^^^^^^^^^^^^^^^^^^^^^^^^^^^^^^^^^^^^^^^^^^^^^^^^
  File "/home/tzikos/anaconda3/envs/KUThesis/lib/python3.12/site-packages/wandb/sdk/lib/gql_request.py", line 58, in execute
    request = self.session.post(self.url, **post_args)
              ^^^^^^^^^^^^^^^^^^^^^^^^^^^^^^^^^^^^^^^^
  File "/home/tzikos/anaconda3/envs/KUThesis/lib/python3.12/site-packages/requests/sessions.py", line 637, in post
    return self.request("POST", url, data=data, json=json, **kwargs)
           ^^^^^^^^^^^^^^^^^^^^^^^^^^^^^^^^^^^^^^^^^^^^^^^^^^^^^^^^^
  File "/home/tzikos/anaconda3/envs/KUThesis/lib/python3.12/site-packages/requests/sessions.py", line 589, in request
    resp = self.send(prep, **send_kwargs)
           ^^^^^^^^^^^^^^^^^^^^^^^^^^^^^^
  File "/home/tzikos/anaconda3/envs/KUThesis/lib/python3.12/site-packages/requests/sessions.py", line 703, in send
    r = adapter.send(request, **kwargs)
        ^^^^^^^^^^^^^^^^^^^^^^^^^^^^^^^
  File "/home/tzikos/anaconda3/envs/KUThesis/lib/python3.12/site-packages/requests/adapters.py", line 519, in send
    raise ConnectionError(e, request=request)
requests.exceptions.ConnectionError: HTTPSConnectionPool(host='api.wandb.ai', port=443): Max retries exceeded with url: /graphql (Caused by NameResolutionError("<urllib3.connection.HTTPSConnection object at 0x79e8be32fe30>: Failed to resolve 'api.wandb.ai' ([Errno -3] Temporary failure in name resolution)"))
2024-06-27 08:43:42,484 INFO    MainThread:306479 [wandb_run.py:_finish():2109] finishing run kuthesis/KU AI Thesis/iefu1zd6
2024-06-27 08:43:42,484 INFO    MainThread:306479 [wandb_run.py:_atexit_cleanup():2349] got exitcode: 0
2024-06-27 08:43:42,484 INFO    MainThread:306479 [wandb_run.py:_restore():2332] restore
2024-06-27 08:43:42,485 INFO    MainThread:306479 [wandb_run.py:_restore():2338] restore done
2024-06-27 08:43:52,034 INFO    MainThread:306479 [wandb_run.py:_footer_history_summary_info():4008] rendering history
2024-06-27 08:43:52,037 INFO    MainThread:306479 [wandb_run.py:_footer_history_summary_info():4040] rendering summary
2024-06-27 08:43:52,043 INFO    MainThread:306479 [wandb_run.py:_footer_sync_info():3967] logging synced files
