2024-05-15 10:08:25,980 INFO    StreamThr :964760 [internal.py:wandb_internal():86] W&B internal server running at pid: 964760, started at: 2024-05-15 10:08:25.979704
2024-05-15 10:08:25,985 DEBUG   HandlerThread:964760 [handler.py:handle_request():146] handle_request: status
2024-05-15 10:08:25,989 INFO    WriterThread:964760 [datastore.py:open_for_write():87] open: /home/tzikos/Desktop/KULeuvenThesis/wandb/run-20240515_100825-1i1ihxwr/run-1i1ihxwr.wandb
2024-05-15 10:08:25,990 DEBUG   SenderThread:964760 [sender.py:send():378] send: header
2024-05-15 10:08:25,990 DEBUG   SenderThread:964760 [sender.py:send():378] send: run
2024-05-15 10:08:30,994 DEBUG   HandlerThread:964760 [handler.py:handle_request():146] handle_request: keepalive
2024-05-15 10:08:35,999 DEBUG   HandlerThread:964760 [handler.py:handle_request():146] handle_request: keepalive
2024-05-15 10:08:41,001 DEBUG   HandlerThread:964760 [handler.py:handle_request():146] handle_request: keepalive
2024-05-15 10:08:46,003 DEBUG   HandlerThread:964760 [handler.py:handle_request():146] handle_request: keepalive
2024-05-15 10:08:51,005 DEBUG   HandlerThread:964760 [handler.py:handle_request():146] handle_request: keepalive
2024-05-15 10:08:56,006 DEBUG   HandlerThread:964760 [handler.py:handle_request():146] handle_request: keepalive
2024-05-15 10:09:01,009 DEBUG   HandlerThread:964760 [handler.py:handle_request():146] handle_request: keepalive
2024-05-15 10:09:06,011 DEBUG   HandlerThread:964760 [handler.py:handle_request():146] handle_request: keepalive
2024-05-15 10:09:11,015 DEBUG   HandlerThread:964760 [handler.py:handle_request():146] handle_request: keepalive
2024-05-15 10:09:16,019 DEBUG   HandlerThread:964760 [handler.py:handle_request():146] handle_request: keepalive
2024-05-15 10:09:21,022 DEBUG   HandlerThread:964760 [handler.py:handle_request():146] handle_request: keepalive
2024-05-15 10:09:26,025 DEBUG   HandlerThread:964760 [handler.py:handle_request():146] handle_request: keepalive
2024-05-15 10:09:29,227 INFO    SenderThread:964760 [retry.py:__call__():172] Retry attempt failed:
Traceback (most recent call last):
  File "/home/tzikos/anaconda3/envs/KUThesis/lib/python3.12/site-packages/urllib3/connection.py", line 198, in _new_conn
    sock = connection.create_connection(
           ^^^^^^^^^^^^^^^^^^^^^^^^^^^^^
  File "/home/tzikos/anaconda3/envs/KUThesis/lib/python3.12/site-packages/urllib3/util/connection.py", line 60, in create_connection
    for res in socket.getaddrinfo(host, port, family, socket.SOCK_STREAM):
               ^^^^^^^^^^^^^^^^^^^^^^^^^^^^^^^^^^^^^^^^^^^^^^^^^^^^^^^^^^
  File "/home/tzikos/anaconda3/envs/KUThesis/lib/python3.12/socket.py", line 963, in getaddrinfo
    for res in _socket.getaddrinfo(host, port, family, type, proto, flags):
               ^^^^^^^^^^^^^^^^^^^^^^^^^^^^^^^^^^^^^^^^^^^^^^^^^^^^^^^^^^^
socket.gaierror: [Errno -3] Temporary failure in name resolution

The above exception was the direct cause of the following exception:

Traceback (most recent call last):
  File "/home/tzikos/anaconda3/envs/KUThesis/lib/python3.12/site-packages/urllib3/connectionpool.py", line 793, in urlopen
    response = self._make_request(
               ^^^^^^^^^^^^^^^^^^^
  File "/home/tzikos/anaconda3/envs/KUThesis/lib/python3.12/site-packages/urllib3/connectionpool.py", line 491, in _make_request
    raise new_e
  File "/home/tzikos/anaconda3/envs/KUThesis/lib/python3.12/site-packages/urllib3/connectionpool.py", line 467, in _make_request
    self._validate_conn(conn)
  File "/home/tzikos/anaconda3/envs/KUThesis/lib/python3.12/site-packages/urllib3/connectionpool.py", line 1099, in _validate_conn
    conn.connect()
  File "/home/tzikos/anaconda3/envs/KUThesis/lib/python3.12/site-packages/urllib3/connection.py", line 616, in connect
    self.sock = sock = self._new_conn()
                       ^^^^^^^^^^^^^^^^
  File "/home/tzikos/anaconda3/envs/KUThesis/lib/python3.12/site-packages/urllib3/connection.py", line 205, in _new_conn
    raise NameResolutionError(self.host, self, e) from e
urllib3.exceptions.NameResolutionError: <urllib3.connection.HTTPSConnection object at 0x7a4a8048e240>: Failed to resolve 'api.wandb.ai' ([Errno -3] Temporary failure in name resolution)

The above exception was the direct cause of the following exception:

Traceback (most recent call last):
  File "/home/tzikos/anaconda3/envs/KUThesis/lib/python3.12/site-packages/requests/adapters.py", line 486, in send
    resp = conn.urlopen(
           ^^^^^^^^^^^^^
  File "/home/tzikos/anaconda3/envs/KUThesis/lib/python3.12/site-packages/urllib3/connectionpool.py", line 847, in urlopen
    retries = retries.increment(
              ^^^^^^^^^^^^^^^^^^
  File "/home/tzikos/anaconda3/envs/KUThesis/lib/python3.12/site-packages/urllib3/util/retry.py", line 515, in increment
    raise MaxRetryError(_pool, url, reason) from reason  # type: ignore[arg-type]
    ^^^^^^^^^^^^^^^^^^^^^^^^^^^^^^^^^^^^^^^^^^^^^^^^^^^
urllib3.exceptions.MaxRetryError: HTTPSConnectionPool(host='api.wandb.ai', port=443): Max retries exceeded with url: /graphql (Caused by NameResolutionError("<urllib3.connection.HTTPSConnection object at 0x7a4a8048e240>: Failed to resolve 'api.wandb.ai' ([Errno -3] Temporary failure in name resolution)"))

During handling of the above exception, another exception occurred:

Traceback (most recent call last):
  File "/home/tzikos/anaconda3/envs/KUThesis/lib/python3.12/site-packages/wandb/sdk/lib/retry.py", line 131, in __call__
    result = self._call_fn(*args, **kwargs)
             ^^^^^^^^^^^^^^^^^^^^^^^^^^^^^^
  File "/home/tzikos/anaconda3/envs/KUThesis/lib/python3.12/site-packages/wandb/sdk/internal/internal_api.py", line 369, in execute
    return self.client.execute(*args, **kwargs)  # type: ignore
           ^^^^^^^^^^^^^^^^^^^^^^^^^^^^^^^^^^^^
  File "/home/tzikos/anaconda3/envs/KUThesis/lib/python3.12/site-packages/wandb/vendor/gql-0.2.0/wandb_gql/client.py", line 52, in execute
    result = self._get_result(document, *args, **kwargs)
             ^^^^^^^^^^^^^^^^^^^^^^^^^^^^^^^^^^^^^^^^^^^
  File "/home/tzikos/anaconda3/envs/KUThesis/lib/python3.12/site-packages/wandb/vendor/gql-0.2.0/wandb_gql/client.py", line 60, in _get_result
    return self.transport.execute(document, *args, **kwargs)
           ^^^^^^^^^^^^^^^^^^^^^^^^^^^^^^^^^^^^^^^^^^^^^^^^^
  File "/home/tzikos/anaconda3/envs/KUThesis/lib/python3.12/site-packages/wandb/sdk/lib/gql_request.py", line 58, in execute
    request = self.session.post(self.url, **post_args)
              ^^^^^^^^^^^^^^^^^^^^^^^^^^^^^^^^^^^^^^^^
  File "/home/tzikos/anaconda3/envs/KUThesis/lib/python3.12/site-packages/requests/sessions.py", line 637, in post
    return self.request("POST", url, data=data, json=json, **kwargs)
           ^^^^^^^^^^^^^^^^^^^^^^^^^^^^^^^^^^^^^^^^^^^^^^^^^^^^^^^^^
  File "/home/tzikos/anaconda3/envs/KUThesis/lib/python3.12/site-packages/requests/sessions.py", line 589, in request
    resp = self.send(prep, **send_kwargs)
           ^^^^^^^^^^^^^^^^^^^^^^^^^^^^^^
  File "/home/tzikos/anaconda3/envs/KUThesis/lib/python3.12/site-packages/requests/sessions.py", line 703, in send
    r = adapter.send(request, **kwargs)
        ^^^^^^^^^^^^^^^^^^^^^^^^^^^^^^^
  File "/home/tzikos/anaconda3/envs/KUThesis/lib/python3.12/site-packages/requests/adapters.py", line 519, in send
    raise ConnectionError(e, request=request)
requests.exceptions.ConnectionError: HTTPSConnectionPool(host='api.wandb.ai', port=443): Max retries exceeded with url: /graphql (Caused by NameResolutionError("<urllib3.connection.HTTPSConnection object at 0x7a4a8048e240>: Failed to resolve 'api.wandb.ai' ([Errno -3] Temporary failure in name resolution)"))
2024-05-15 10:09:31,026 DEBUG   HandlerThread:964760 [handler.py:handle_request():146] handle_request: keepalive
2024-05-15 10:09:36,030 DEBUG   HandlerThread:964760 [handler.py:handle_request():146] handle_request: keepalive
2024-05-15 10:09:41,033 DEBUG   HandlerThread:964760 [handler.py:handle_request():146] handle_request: keepalive
2024-05-15 10:09:46,036 DEBUG   HandlerThread:964760 [handler.py:handle_request():146] handle_request: keepalive
2024-05-15 10:09:51,040 DEBUG   HandlerThread:964760 [handler.py:handle_request():146] handle_request: keepalive
2024-05-15 10:09:56,042 DEBUG   HandlerThread:964760 [handler.py:handle_request():146] handle_request: cancel
2024-05-15 10:09:56,042 DEBUG   HandlerThread:964760 [handler.py:handle_request():146] handle_request: cancel
2024-05-15 10:09:56,043 DEBUG   SenderThread:964760 [sender.py:send():387] Record cancelled: run
2024-05-15 10:09:56,043 DEBUG   HandlerThread:964760 [handler.py:handle_request():146] handle_request: status_report
2024-05-15 10:10:01,047 DEBUG   HandlerThread:964760 [handler.py:handle_request():146] handle_request: status_report
2024-05-15 10:10:06,050 DEBUG   HandlerThread:964760 [handler.py:handle_request():146] handle_request: status_report
