2024-05-15 10:08:25,974 INFO    MainThread:964639 [wandb_setup.py:_flush():76] Current SDK version is 0.16.4
2024-05-15 10:08:25,974 INFO    MainThread:964639 [wandb_setup.py:_flush():76] Configure stats pid to 964639
2024-05-15 10:08:25,974 INFO    MainThread:964639 [wandb_setup.py:_flush():76] Loading settings from /home/tzikos/.config/wandb/settings
2024-05-15 10:08:25,974 INFO    MainThread:964639 [wandb_setup.py:_flush():76] Loading settings from /home/tzikos/Desktop/KULeuvenThesis/wandb/settings
2024-05-15 10:08:25,974 INFO    MainThread:964639 [wandb_setup.py:_flush():76] Loading settings from environment variables: {}
2024-05-15 10:08:25,974 INFO    MainThread:964639 [wandb_setup.py:_flush():76] Applying setup settings: {'_disable_service': False}
2024-05-15 10:08:25,974 INFO    MainThread:964639 [wandb_setup.py:_flush():76] Inferring run settings from compute environment: {'program_relpath': 'main.py', 'program_abspath': '/home/tzikos/Desktop/KULeuvenThesis/main.py', 'program': '/home/tzikos/Desktop/KULeuvenThesis/main.py'}
2024-05-15 10:08:25,975 INFO    MainThread:964639 [wandb_init.py:_log_setup():526] Logging user logs to /home/tzikos/Desktop/KULeuvenThesis/wandb/run-20240515_100825-1i1ihxwr/logs/debug.log
2024-05-15 10:08:25,975 INFO    MainThread:964639 [wandb_init.py:_log_setup():527] Logging internal logs to /home/tzikos/Desktop/KULeuvenThesis/wandb/run-20240515_100825-1i1ihxwr/logs/debug-internal.log
2024-05-15 10:08:25,975 INFO    MainThread:964639 [wandb_init.py:init():566] calling init triggers
2024-05-15 10:08:25,975 INFO    MainThread:964639 [wandb_init.py:init():573] wandb.init called with sweep_config: {}
config: {'learning_rate': 1e-07, 'batch_size': 64, 'L1': None, 'L2': None, 'A': 1, 'early_patience': 12, 'reduce_lr_patience': 5, 'architecture': 'ECGCNNClassifier', 'experiment': 'pre', 'use_pretrained': False}
2024-05-15 10:08:25,975 INFO    MainThread:964639 [wandb_init.py:init():616] starting backend
2024-05-15 10:08:25,975 INFO    MainThread:964639 [wandb_init.py:init():620] setting up manager
2024-05-15 10:08:25,976 INFO    MainThread:964639 [backend.py:_multiprocessing_setup():105] multiprocessing start_methods=fork,spawn,forkserver, using: spawn
2024-05-15 10:08:25,978 INFO    MainThread:964639 [wandb_init.py:init():628] backend started and connected
2024-05-15 10:08:25,984 INFO    MainThread:964639 [wandb_init.py:init():720] updated telemetry
2024-05-15 10:08:25,989 INFO    MainThread:964639 [wandb_init.py:init():753] communicating run to backend with 90.0 second timeout
2024-05-15 10:09:24,210 INFO    Thread-7 (wrapped_target):964639 [retry.py:__call__():172] Retry attempt failed:
Traceback (most recent call last):
  File "/home/tzikos/anaconda3/envs/KUThesis/lib/python3.12/site-packages/urllib3/connection.py", line 198, in _new_conn
    sock = connection.create_connection(
           ^^^^^^^^^^^^^^^^^^^^^^^^^^^^^
  File "/home/tzikos/anaconda3/envs/KUThesis/lib/python3.12/site-packages/urllib3/util/connection.py", line 60, in create_connection
    for res in socket.getaddrinfo(host, port, family, socket.SOCK_STREAM):
               ^^^^^^^^^^^^^^^^^^^^^^^^^^^^^^^^^^^^^^^^^^^^^^^^^^^^^^^^^^
  File "/home/tzikos/anaconda3/envs/KUThesis/lib/python3.12/socket.py", line 963, in getaddrinfo
    for res in _socket.getaddrinfo(host, port, family, type, proto, flags):
               ^^^^^^^^^^^^^^^^^^^^^^^^^^^^^^^^^^^^^^^^^^^^^^^^^^^^^^^^^^^
socket.gaierror: [Errno -3] Temporary failure in name resolution

The above exception was the direct cause of the following exception:

Traceback (most recent call last):
  File "/home/tzikos/anaconda3/envs/KUThesis/lib/python3.12/site-packages/urllib3/connectionpool.py", line 793, in urlopen
    response = self._make_request(
               ^^^^^^^^^^^^^^^^^^^
  File "/home/tzikos/anaconda3/envs/KUThesis/lib/python3.12/site-packages/urllib3/connectionpool.py", line 491, in _make_request
    raise new_e
  File "/home/tzikos/anaconda3/envs/KUThesis/lib/python3.12/site-packages/urllib3/connectionpool.py", line 467, in _make_request
    self._validate_conn(conn)
  File "/home/tzikos/anaconda3/envs/KUThesis/lib/python3.12/site-packages/urllib3/connectionpool.py", line 1099, in _validate_conn
    conn.connect()
  File "/home/tzikos/anaconda3/envs/KUThesis/lib/python3.12/site-packages/urllib3/connection.py", line 616, in connect
    self.sock = sock = self._new_conn()
                       ^^^^^^^^^^^^^^^^
  File "/home/tzikos/anaconda3/envs/KUThesis/lib/python3.12/site-packages/urllib3/connection.py", line 205, in _new_conn
    raise NameResolutionError(self.host, self, e) from e
urllib3.exceptions.NameResolutionError: <urllib3.connection.HTTPSConnection object at 0x7a0dc00f1400>: Failed to resolve 'api.wandb.ai' ([Errno -3] Temporary failure in name resolution)

The above exception was the direct cause of the following exception:

Traceback (most recent call last):
  File "/home/tzikos/anaconda3/envs/KUThesis/lib/python3.12/site-packages/requests/adapters.py", line 486, in send
    resp = conn.urlopen(
           ^^^^^^^^^^^^^
  File "/home/tzikos/anaconda3/envs/KUThesis/lib/python3.12/site-packages/urllib3/connectionpool.py", line 847, in urlopen
    retries = retries.increment(
              ^^^^^^^^^^^^^^^^^^
  File "/home/tzikos/anaconda3/envs/KUThesis/lib/python3.12/site-packages/urllib3/util/retry.py", line 515, in increment
    raise MaxRetryError(_pool, url, reason) from reason  # type: ignore[arg-type]
    ^^^^^^^^^^^^^^^^^^^^^^^^^^^^^^^^^^^^^^^^^^^^^^^^^^^
urllib3.exceptions.MaxRetryError: HTTPSConnectionPool(host='api.wandb.ai', port=443): Max retries exceeded with url: /graphql (Caused by NameResolutionError("<urllib3.connection.HTTPSConnection object at 0x7a0dc00f1400>: Failed to resolve 'api.wandb.ai' ([Errno -3] Temporary failure in name resolution)"))

During handling of the above exception, another exception occurred:

Traceback (most recent call last):
  File "/home/tzikos/anaconda3/envs/KUThesis/lib/python3.12/site-packages/wandb/sdk/lib/retry.py", line 131, in __call__
    result = self._call_fn(*args, **kwargs)
             ^^^^^^^^^^^^^^^^^^^^^^^^^^^^^^
  File "/home/tzikos/anaconda3/envs/KUThesis/lib/python3.12/site-packages/wandb/sdk/internal/internal_api.py", line 369, in execute
    return self.client.execute(*args, **kwargs)  # type: ignore
           ^^^^^^^^^^^^^^^^^^^^^^^^^^^^^^^^^^^^
  File "/home/tzikos/anaconda3/envs/KUThesis/lib/python3.12/site-packages/wandb/vendor/gql-0.2.0/wandb_gql/client.py", line 52, in execute
    result = self._get_result(document, *args, **kwargs)
             ^^^^^^^^^^^^^^^^^^^^^^^^^^^^^^^^^^^^^^^^^^^
  File "/home/tzikos/anaconda3/envs/KUThesis/lib/python3.12/site-packages/wandb/vendor/gql-0.2.0/wandb_gql/client.py", line 60, in _get_result
    return self.transport.execute(document, *args, **kwargs)
           ^^^^^^^^^^^^^^^^^^^^^^^^^^^^^^^^^^^^^^^^^^^^^^^^^
  File "/home/tzikos/anaconda3/envs/KUThesis/lib/python3.12/site-packages/wandb/sdk/lib/gql_request.py", line 58, in execute
    request = self.session.post(self.url, **post_args)
              ^^^^^^^^^^^^^^^^^^^^^^^^^^^^^^^^^^^^^^^^
  File "/home/tzikos/anaconda3/envs/KUThesis/lib/python3.12/site-packages/requests/sessions.py", line 637, in post
    return self.request("POST", url, data=data, json=json, **kwargs)
           ^^^^^^^^^^^^^^^^^^^^^^^^^^^^^^^^^^^^^^^^^^^^^^^^^^^^^^^^^
  File "/home/tzikos/anaconda3/envs/KUThesis/lib/python3.12/site-packages/requests/sessions.py", line 589, in request
    resp = self.send(prep, **send_kwargs)
           ^^^^^^^^^^^^^^^^^^^^^^^^^^^^^^
  File "/home/tzikos/anaconda3/envs/KUThesis/lib/python3.12/site-packages/requests/sessions.py", line 703, in send
    r = adapter.send(request, **kwargs)
        ^^^^^^^^^^^^^^^^^^^^^^^^^^^^^^^
  File "/home/tzikos/anaconda3/envs/KUThesis/lib/python3.12/site-packages/requests/adapters.py", line 519, in send
    raise ConnectionError(e, request=request)
requests.exceptions.ConnectionError: HTTPSConnectionPool(host='api.wandb.ai', port=443): Max retries exceeded with url: /graphql (Caused by NameResolutionError("<urllib3.connection.HTTPSConnection object at 0x7a0dc00f1400>: Failed to resolve 'api.wandb.ai' ([Errno -3] Temporary failure in name resolution)"))
2024-05-15 10:09:56,042 ERROR   MainThread:964639 [wandb_init.py:init():779] encountered error: Run initialization has timed out after 90.0 sec. 
Please refer to the documentation for additional information: https://docs.wandb.ai/guides/track/tracking-faq#initstarterror-error-communicating-with-wandb-process-
2024-05-15 10:09:58,052 ERROR   MainThread:964639 [wandb_init.py:init():1194] Run initialization has timed out after 90.0 sec. 
Please refer to the documentation for additional information: https://docs.wandb.ai/guides/track/tracking-faq#initstarterror-error-communicating-with-wandb-process-
Traceback (most recent call last):
  File "/home/tzikos/anaconda3/envs/KUThesis/lib/python3.12/site-packages/wandb/sdk/wandb_init.py", line 1176, in init
    run = wi.init()
          ^^^^^^^^^
  File "/home/tzikos/anaconda3/envs/KUThesis/lib/python3.12/site-packages/wandb/sdk/wandb_init.py", line 785, in init
    raise error
wandb.errors.CommError: Run initialization has timed out after 90.0 sec. 
Please refer to the documentation for additional information: https://docs.wandb.ai/guides/track/tracking-faq#initstarterror-error-communicating-with-wandb-process-
