2024-05-11 15:56:05,352 INFO    StreamThr :4605 [internal.py:wandb_internal():86] W&B internal server running at pid: 4605, started at: 2024-05-11 15:56:05.350884
2024-05-11 15:56:05,357 DEBUG   HandlerThread:4605 [handler.py:handle_request():146] handle_request: status
2024-05-11 15:56:05,364 INFO    WriterThread:4605 [datastore.py:open_for_write():87] open: /home/tzikos/Desktop/KULeuvenThesis/wandb/run-20240511_155605-ibkdknv7/run-ibkdknv7.wandb
2024-05-11 15:56:05,365 DEBUG   SenderThread:4605 [sender.py:send():378] send: header
2024-05-11 15:56:05,365 DEBUG   SenderThread:4605 [sender.py:send():378] send: run
2024-05-11 15:56:10,366 DEBUG   HandlerThread:4605 [handler.py:handle_request():146] handle_request: keepalive
2024-05-11 15:56:15,368 DEBUG   HandlerThread:4605 [handler.py:handle_request():146] handle_request: keepalive
2024-05-11 15:56:20,371 DEBUG   HandlerThread:4605 [handler.py:handle_request():146] handle_request: keepalive
2024-05-11 15:56:25,373 DEBUG   HandlerThread:4605 [handler.py:handle_request():146] handle_request: keepalive
2024-05-11 15:56:30,376 DEBUG   HandlerThread:4605 [handler.py:handle_request():146] handle_request: keepalive
2024-05-11 15:56:35,378 DEBUG   HandlerThread:4605 [handler.py:handle_request():146] handle_request: keepalive
2024-05-11 15:56:40,380 DEBUG   HandlerThread:4605 [handler.py:handle_request():146] handle_request: keepalive
2024-05-11 15:56:45,383 DEBUG   HandlerThread:4605 [handler.py:handle_request():146] handle_request: keepalive
2024-05-11 15:56:50,385 DEBUG   HandlerThread:4605 [handler.py:handle_request():146] handle_request: keepalive
2024-05-11 15:56:55,388 DEBUG   HandlerThread:4605 [handler.py:handle_request():146] handle_request: keepalive
2024-05-11 15:57:00,389 DEBUG   HandlerThread:4605 [handler.py:handle_request():146] handle_request: keepalive
2024-05-11 15:57:05,391 DEBUG   HandlerThread:4605 [handler.py:handle_request():146] handle_request: keepalive
2024-05-11 15:57:08,940 INFO    SenderThread:4605 [retry.py:__call__():172] Retry attempt failed:
Traceback (most recent call last):
  File "/home/tzikos/anaconda3/envs/KUThesis/lib/python3.12/site-packages/urllib3/connection.py", line 198, in _new_conn
    sock = connection.create_connection(
           ^^^^^^^^^^^^^^^^^^^^^^^^^^^^^
  File "/home/tzikos/anaconda3/envs/KUThesis/lib/python3.12/site-packages/urllib3/util/connection.py", line 60, in create_connection
    for res in socket.getaddrinfo(host, port, family, socket.SOCK_STREAM):
               ^^^^^^^^^^^^^^^^^^^^^^^^^^^^^^^^^^^^^^^^^^^^^^^^^^^^^^^^^^
  File "/home/tzikos/anaconda3/envs/KUThesis/lib/python3.12/socket.py", line 963, in getaddrinfo
    for res in _socket.getaddrinfo(host, port, family, type, proto, flags):
               ^^^^^^^^^^^^^^^^^^^^^^^^^^^^^^^^^^^^^^^^^^^^^^^^^^^^^^^^^^^
socket.gaierror: [Errno -3] Temporary failure in name resolution

The above exception was the direct cause of the following exception:

Traceback (most recent call last):
  File "/home/tzikos/anaconda3/envs/KUThesis/lib/python3.12/site-packages/urllib3/connectionpool.py", line 793, in urlopen
    response = self._make_request(
               ^^^^^^^^^^^^^^^^^^^
  File "/home/tzikos/anaconda3/envs/KUThesis/lib/python3.12/site-packages/urllib3/connectionpool.py", line 491, in _make_request
    raise new_e
  File "/home/tzikos/anaconda3/envs/KUThesis/lib/python3.12/site-packages/urllib3/connectionpool.py", line 467, in _make_request
    self._validate_conn(conn)
  File "/home/tzikos/anaconda3/envs/KUThesis/lib/python3.12/site-packages/urllib3/connectionpool.py", line 1099, in _validate_conn
    conn.connect()
  File "/home/tzikos/anaconda3/envs/KUThesis/lib/python3.12/site-packages/urllib3/connection.py", line 616, in connect
    self.sock = sock = self._new_conn()
                       ^^^^^^^^^^^^^^^^
  File "/home/tzikos/anaconda3/envs/KUThesis/lib/python3.12/site-packages/urllib3/connection.py", line 205, in _new_conn
    raise NameResolutionError(self.host, self, e) from e
urllib3.exceptions.NameResolutionError: <urllib3.connection.HTTPSConnection object at 0x720f7cf8e150>: Failed to resolve 'api.wandb.ai' ([Errno -3] Temporary failure in name resolution)

The above exception was the direct cause of the following exception:

Traceback (most recent call last):
  File "/home/tzikos/anaconda3/envs/KUThesis/lib/python3.12/site-packages/requests/adapters.py", line 486, in send
    resp = conn.urlopen(
           ^^^^^^^^^^^^^
  File "/home/tzikos/anaconda3/envs/KUThesis/lib/python3.12/site-packages/urllib3/connectionpool.py", line 847, in urlopen
    retries = retries.increment(
              ^^^^^^^^^^^^^^^^^^
  File "/home/tzikos/anaconda3/envs/KUThesis/lib/python3.12/site-packages/urllib3/util/retry.py", line 515, in increment
    raise MaxRetryError(_pool, url, reason) from reason  # type: ignore[arg-type]
    ^^^^^^^^^^^^^^^^^^^^^^^^^^^^^^^^^^^^^^^^^^^^^^^^^^^
urllib3.exceptions.MaxRetryError: HTTPSConnectionPool(host='api.wandb.ai', port=443): Max retries exceeded with url: /graphql (Caused by NameResolutionError("<urllib3.connection.HTTPSConnection object at 0x720f7cf8e150>: Failed to resolve 'api.wandb.ai' ([Errno -3] Temporary failure in name resolution)"))

During handling of the above exception, another exception occurred:

Traceback (most recent call last):
  File "/home/tzikos/anaconda3/envs/KUThesis/lib/python3.12/site-packages/wandb/sdk/lib/retry.py", line 131, in __call__
    result = self._call_fn(*args, **kwargs)
             ^^^^^^^^^^^^^^^^^^^^^^^^^^^^^^
  File "/home/tzikos/anaconda3/envs/KUThesis/lib/python3.12/site-packages/wandb/sdk/internal/internal_api.py", line 369, in execute
    return self.client.execute(*args, **kwargs)  # type: ignore
           ^^^^^^^^^^^^^^^^^^^^^^^^^^^^^^^^^^^^
  File "/home/tzikos/anaconda3/envs/KUThesis/lib/python3.12/site-packages/wandb/vendor/gql-0.2.0/wandb_gql/client.py", line 52, in execute
    result = self._get_result(document, *args, **kwargs)
             ^^^^^^^^^^^^^^^^^^^^^^^^^^^^^^^^^^^^^^^^^^^
  File "/home/tzikos/anaconda3/envs/KUThesis/lib/python3.12/site-packages/wandb/vendor/gql-0.2.0/wandb_gql/client.py", line 60, in _get_result
    return self.transport.execute(document, *args, **kwargs)
           ^^^^^^^^^^^^^^^^^^^^^^^^^^^^^^^^^^^^^^^^^^^^^^^^^
  File "/home/tzikos/anaconda3/envs/KUThesis/lib/python3.12/site-packages/wandb/sdk/lib/gql_request.py", line 58, in execute
    request = self.session.post(self.url, **post_args)
              ^^^^^^^^^^^^^^^^^^^^^^^^^^^^^^^^^^^^^^^^
  File "/home/tzikos/anaconda3/envs/KUThesis/lib/python3.12/site-packages/requests/sessions.py", line 637, in post
    return self.request("POST", url, data=data, json=json, **kwargs)
           ^^^^^^^^^^^^^^^^^^^^^^^^^^^^^^^^^^^^^^^^^^^^^^^^^^^^^^^^^
  File "/home/tzikos/anaconda3/envs/KUThesis/lib/python3.12/site-packages/requests/sessions.py", line 589, in request
    resp = self.send(prep, **send_kwargs)
           ^^^^^^^^^^^^^^^^^^^^^^^^^^^^^^
  File "/home/tzikos/anaconda3/envs/KUThesis/lib/python3.12/site-packages/requests/sessions.py", line 703, in send
    r = adapter.send(request, **kwargs)
        ^^^^^^^^^^^^^^^^^^^^^^^^^^^^^^^
  File "/home/tzikos/anaconda3/envs/KUThesis/lib/python3.12/site-packages/requests/adapters.py", line 519, in send
    raise ConnectionError(e, request=request)
requests.exceptions.ConnectionError: HTTPSConnectionPool(host='api.wandb.ai', port=443): Max retries exceeded with url: /graphql (Caused by NameResolutionError("<urllib3.connection.HTTPSConnection object at 0x720f7cf8e150>: Failed to resolve 'api.wandb.ai' ([Errno -3] Temporary failure in name resolution)"))
2024-05-11 15:57:10,394 DEBUG   HandlerThread:4605 [handler.py:handle_request():146] handle_request: keepalive
2024-05-11 15:57:15,396 DEBUG   HandlerThread:4605 [handler.py:handle_request():146] handle_request: keepalive
2024-05-11 15:57:20,399 DEBUG   HandlerThread:4605 [handler.py:handle_request():146] handle_request: keepalive
2024-05-11 15:57:25,401 DEBUG   HandlerThread:4605 [handler.py:handle_request():146] handle_request: keepalive
2024-05-11 15:57:30,403 DEBUG   HandlerThread:4605 [handler.py:handle_request():146] handle_request: keepalive
2024-05-11 15:57:35,405 DEBUG   HandlerThread:4605 [handler.py:handle_request():146] handle_request: cancel
2024-05-11 15:57:35,405 DEBUG   HandlerThread:4605 [handler.py:handle_request():146] handle_request: cancel
2024-05-11 15:57:41,631 INFO    SenderThread:4605 [dir_watcher.py:__init__():211] watching files in: /home/tzikos/Desktop/KULeuvenThesis/wandb/run-20240511_155605-ibkdknv7/files
2024-05-11 15:57:41,631 INFO    SenderThread:4605 [sender.py:_start_run_threads():1099] run started: ibkdknv7 with start time 1715435765.349998
2024-05-11 15:57:41,632 DEBUG   HandlerThread:4605 [handler.py:handle_request():146] handle_request: status_report
2024-05-11 15:57:46,634 DEBUG   HandlerThread:4605 [handler.py:handle_request():146] handle_request: status_report
2024-05-11 15:57:51,635 DEBUG   HandlerThread:4605 [handler.py:handle_request():146] handle_request: status_report
2024-05-11 15:57:56,638 DEBUG   HandlerThread:4605 [handler.py:handle_request():146] handle_request: status_report
2024-05-11 15:58:01,642 DEBUG   HandlerThread:4605 [handler.py:handle_request():146] handle_request: status_report
2024-05-11 15:58:06,646 DEBUG   HandlerThread:4605 [handler.py:handle_request():146] handle_request: status_report
2024-05-11 15:58:11,649 DEBUG   HandlerThread:4605 [handler.py:handle_request():146] handle_request: status_report
2024-05-11 15:58:16,654 DEBUG   HandlerThread:4605 [handler.py:handle_request():146] handle_request: status_report
